Workbook

Sheet Summary
A1: Deemed Health · Financial summary
A2: Launch period = October 2026 – December 2027. Cash view; no financing income or taxes.
A3: Line | B3: Launch period | C3: 2028 | D3: 2029 | E3: 2030 | F3: 2031
A4: Revenue | B4: =Revenue!C11 -> 28800 | C4: =Revenue!D11 -> 360000 | D4: =Revenue!E11 -> 766272 | E4: =Revenue!F11 -> 1171941.1 | F4: =Revenue!G11 -> 1539115.3
A5: Costs | B5: ='Launch budget'!F53 -> 953167.22 | C5: ='Operating budget'!D42 -> 1149077.6 | D5: ='Operating budget'!E42 -> 1304903.2 | E5: ='Operating budget'!F42 -> 1376377.7 | F5: ='Operating budget'!G42 -> 1425655.9
A6: Net cash flow | B6: =B4-B5 -> -924367.22 | C6: =C4-C5 -> -789077.6 | D6: =D4-D5 -> -538631.16 | E6: =E4-E5 -> -204436.56 | F6: =F4-F5 -> 113459.32
A7: Cumulative cash position | B7: =B6 -> -924367.22 | C7: =B7+C6 -> -1713444.8 | D7: =C7+D6 -> -2252076 | E7: =D7+E6 -> -2456512.5 | F7: =E7+F6 -> -2343053.2
A8: Year-end customers | B8: =Revenue!C5 -> 2 | C8: =Revenue!D5 -> 8 | D8: =Revenue!E5 -> 15 | E8: =Revenue!F5 -> 21 | F8: =Revenue!G5 -> 26
A9: Annual recurring revenue at year end | B9: =Revenue!C12 -> 115200 | C9: =Revenue!D12 -> 460800 | D9: =Revenue!E12 -> 889920 | E9: =Revenue!F12 -> 1283264.6 | F9: =Revenue!G12 -> 1636468
A10: Customers needed to cover the year's costs | C10: =C5/Revenue!D7 -> 19.949264 | D10: =D5/Revenue!E7 -> 21.994727 | E10: =E5/Revenue!F7 -> 22.523749 | F10: =F5/Revenue!G7 -> 22.650645
A12: Funding required (deepest cumulative cash position) | B12: =-MIN(0,B7,C7,D7,E7,F7) -> 2456512.5
A13: Recommended raise (funding required + 6 months of 2028 costs) | B13: =B12+C5/2 -> 3031051.3

Sheet Assumptions
A1: Deemed Health · Model assumptions
A2: Blue values are inputs. Every other sheet calculates from them.
A3: Input | B3: Value | C3: Note
A4: Florida FQHC organizations (HRSA awardees + Look-Alikes) | B4: 52 | C4: Planning estimate; verify against HRSA UDS state data (data.hrsa.gov) before external use
A5: Essentials tier: annual subscription (< 20,000 patients) | B5: 36000
A6: Professional tier: annual subscription (20,000–60,000 patients) | B6: 60000
A7: Enterprise tier: annual subscription (> 60,000 patients) | B7: 96000
A8: Customer mix: Essentials | B8: 0.4
A9: Customer mix: Professional | B9: 0.4
A10: Customer mix: Enterprise | B10: 0.2
A11: Implementation fee: Essentials (one-time) | B11: 7500 | C11: Data import, SSO, training
A12: Implementation fee: Professional (one-time) | B12: 12500
A13: Implementation fee: Enterprise (one-time) | B13: 20000
A14: Annual price increase (from 2029) | B14: 0.03
A15: Design-partner (pilot) discount | B15: 0.5 | C15: Implementation fee waived for pilots
A16: Pilot months billed in 2027 | B16: 6 | C16: Jul–Dec 2027 (Phase 5)
A17: Customers at year end 2027 (pilots) | B17: 2 | C17: Pilots convert to full price Jan 2028
A18: Customers at year end 2028 | B18: 8 | C18: General availability Jan 2028
A19: Customers at year end 2029 | B19: 15
A20: Customers at year end 2030 | B20: 21
A21: Customers at year end 2031 | B21: 26 | C21: Half of the Florida market
A22: Payroll taxes and benefits (% of salary) | B22: 0.22 | C22: FICA, FUTA/RT-6, health, 401(k), workers' comp
A23: Annual salary increase | B23: 0.04
A24: Sales commission (% of first-year subscription) | B24: 0.1
A25: AWS fixed monthly run cost (prod + non-prod + security) | B25: 2500 | C25: ADR-0005 account layout, Multi-AZ, DR copies
A26: AWS monthly cost per customer | B26: 150 | C26: Compute, storage, backups
A27: Claude API monthly cost per customer (Deemed Assistant) | B27: 120 | C27: Briefs, intake, panel (Phase 6)
A28: Payment processing (% of revenue) | B28: 0.005 | C28: Mostly ACH invoices
A29: Contingency on launch budget | B29: 0.15
A30: Contingency on operating budget | B30: 0.1
A32: Blended annual subscription (list price) | B32: =PriceEss*MixEss+PricePro*MixPro+PriceEnt*MixEnt -> 57600
A33: Blended implementation fee | B33: =ImplEss*MixEss+ImplPro*MixPro+ImplEnt*MixEnt -> 12000
A34: Florida serviceable market at list price (annual) | B34: =Market*Blended -> 2995200

Sheet Revenue
A1: Deemed Health · Revenue build
A2: 2027 is the paid pilot (design partners). General availability January 2028.
A3: Line | B3: Basis | C3: 2027 | D3: 2028 | E3: 2029 | F3: 2030 | G3: 2031
A4: Customers at year start | B4: Prior year end | C4: 0 | D4: =C5 -> 2 | E4: =D5 -> 8 | F4: =E5 -> 15 | G4: =F5 -> 21
A5: Customers at year end | B5: Assumptions | C5: =Cust2027 -> 2 | D5: =Cust2028 -> 8 | E5: =Cust2029 -> 15 | F5: =Cust2030 -> 21 | G5: =Cust2031 -> 26
A6: Average customers | B6: (Start + end) / 2 | C6: =(C4+C5)/2 -> 1 | D6: =(D4+D5)/2 -> 5 | E6: =(E4+E5)/2 -> 11.5 | F6: =(F4+F5)/2 -> 18 | G6: =(G4+G5)/2 -> 23.5
A7: List subscription per customer | B7: Blended × (1 + Uplift)^(year − 2028) | C7: =Blended*(1+Uplift)^MAX(0,C3-2028) -> 57600 | D7: =Blended*(1+Uplift)^MAX(0,D3-2028) -> 57600 | E7: =Blended*(1+Uplift)^MAX(0,E3-2028) -> 59328 | F7: =Blended*(1+Uplift)^MAX(0,F3-2028) -> 61107.84 | G7: =Blended*(1+Uplift)^MAX(0,G3-2028) -> 62941.075
A8: Subscription revenue | B8: Average × list (2027: pilots at discount) | C8: =C5*Blended*(1-PilotDisc)*PilotMonths/12 -> 28800 | D8: =D6*D7 -> 288000 | E8: =E6*E7 -> 682272 | F8: =F6*F7 -> 1099941.1 | G8: =G6*G7 -> 1479115.3
A9: New customers | B9: End − start | C9: =C5-C4 -> 2 | D9: =D5-D4 -> 6 | E9: =E5-E4 -> 7 | F9: =F5-F4 -> 6 | G9: =G5-G4 -> 5
A10: Implementation revenue | B10: New × blended fee (waived for pilots) | C10: 0 | D10: =D9*BlendedImpl -> 72000 | E10: =E9*BlendedImpl -> 84000 | F10: =F9*BlendedImpl -> 72000 | G10: =G9*BlendedImpl -> 60000
A11: Total revenue | C11: =C8+C10 -> 28800 | D11: =D8+D10 -> 360000 | E11: =E8+E10 -> 766272 | F11: =F8+F10 -> 1171941.1 | G11: =G8+G10 -> 1539115.3
A12: Annual recurring revenue at year end | B12: End × list | C12: =C5*C7 -> 115200 | D12: =D5*D7 -> 460800 | E12: =E5*E7 -> 889920 | F12: =F5*F7 -> 1283264.6 | G12: =G5*G7 -> 1636468
A13: Share of Florida market | B13: End ÷ Market | C13: =C5/Market -> 0.038461538 | D13: =D5/Market -> 0.15384615 | E13: =E5/Market -> 0.28846154 | F13: =F5/Market -> 0.40384615 | G13: =G5/Market -> 0.5

Sheet Launch budget
A1: Deemed Health · Launch budget, October 2026 – December 2027
A2: Everything needed to reach general availability: Phases 1–5 and gates G1–G5 of the implementation roadmap.
A3: Category | B3: Item | C3: Basis | D3: Unit cost | E3: Qty (months or units) | F3: Total | G3: Gate / phase
A4: People | B4: Founder / CEO and product owner (also HIPAA security and privacy officer) | C4: $120k/yr × 15 mo | D4: 10000 | E4: 15 | F4: =D4*E4 -> 150000 | G4: All
A5: People | B5: Senior full-stack engineer (TypeScript, AWS) | C5: $170k/yr from Jan 2027 | D5: 14167 | E5: 12 | F5: =D5*E5 -> 170004 | G5: P1–P5
A6: People | B6: Implementation & customer success lead (bilingual EN/ES, FQHC compliance) | C6: $95k/yr from Jun 2027 | D6: 7917 | E6: 7 | F6: =D6*E6 -> 55419 | G6: P4–P5
A7: People | B7: Sales & partnerships lead (Florida FQHC network) | C7: $105k/yr from Oct 2027 | D7: 8750 | E7: 3 | F7: =D7*E7 -> 26250 | G7: P5
A8: People | B8: Payroll taxes and benefits | C8: Load × salaries above | F8: =Load*(F4+F5+F6+F7) -> 88368.06
A9: People | B9: Fractional HRSA compliance advisor (catalog verification, OSV protocol) | C9: 20 h/mo × $150 | D9: 3000 | E9: 15 | F9: =D9*E9 -> 45000 | G9: G0–G5
A10: People | B10: Fractional CISO / security advisor | C10: $3,500/mo from Jan 2027 | D10: 3500 | E10: 12 | F10: =D10*E10 -> 42000 | G10: G1–G5
A11: People | B11: Recruiting and background checks | C11: Per hire | D11: 2500 | E11: 3 | F11: =D11*E11 -> 7500
A12: Professional services & assurance | B12: Counsel: MSA, terms of service, customer BAA template, privacy policy | C12: Fixed fee | D12: 20000 | E12: 1 | F12: =D12*E12 -> 20000 | G12: G4
A13: Professional services & assurance | B13: Counsel: Florida privacy and breach memo (FIPA §501.171, §408.051) | C13: Fixed fee | D13: 7500 | E13: 1 | F13: =D13*E13 -> 7500 | G13: G4
A14: Professional services & assurance | B14: Counsel: HRSA, NPDB, and CVO regulatory memos (decision D3) | C14: Fixed fee | D14: 7500 | E14: 1 | F14: =D14*E14 -> 7500 | G14: G2
A15: Professional services & assurance | B15: Counsel: design-partner pilot agreement; pricing and contract review | C15: Fixed fee | D15: 6000 | E15: 1 | F15: =D15*E15 -> 6000 | G15: G5
A16: Professional services & assurance | B16: Counsel: employment, contractor, and IP assignment agreements | C16: Fixed fee | D16: 3000 | E16: 1 | F16: =D16*E16 -> 3000 | G16: P1
A17: Professional services & assurance | B17: Trademark: "Deemed Health" USPTO filing, 2 classes | C17: With attorney | D17: 2500 | E17: 1 | F17: =D17*E17 -> 2500
A18: Professional services & assurance | B18: Independent penetration test, including retest | C18: Fixed fee | D18: 25000 | E18: 1 | F18: =D18*E18 -> 25000 | G18: G4
A19: Professional services & assurance | B19: Incident response tabletop facilitation | C19: Fixed fee | D19: 4000 | E19: 1 | F19: =D19*E19 -> 4000 | G19: G4
A20: Professional services & assurance | B20: SOC 2 Type I audit | C20: Audit firm | D20: 20000 | E20: 1 | F20: =D20*E20 -> 20000 | G20: G5
A21: Professional services & assurance | B21: External WCAG 2.1 AA accessibility audit | C21: Fixed fee | D21: 10000 | E21: 1 | F21: =D21*E21 -> 10000 | G21: G2
A22: Professional services & assurance | B22: Professional Spanish translation review (UI, help, templates) | C22: Fixed fee | D22: 10000 | E22: 1 | F22: =D22*E22 -> 10000 | G22: G2
A23: Technology & infrastructure | B23: AWS non-production and security accounts | C23: From Jan 2027 | D23: 700 | E23: 12 | F23: =D23*E23 -> 8400 | G23: P1
A24: Technology & infrastructure | B24: AWS production (Multi-AZ RDS, Fargate, WAF, GuardDuty, DR copies) | C24: From Apr 2027 | D24: 1800 | E24: 9 | F24: =D24*E24 -> 16200 | G24: P4
A25: Technology & infrastructure | B25: Netlify + Neon development environments (synthetic data) | C25: Monthly | D25: 150 | E25: 15 | F25: =D25*E25 -> 2250 | G25: P1
A26: Technology & infrastructure | B26: GitHub Team, Secret Protection, Code Security | C26: Monthly | D26: 200 | E26: 15 | F26: =D26*E26 -> 3000 | G26: G0
A27: Technology & infrastructure | B27: AI development tools (Claude plans for the build team) | C27: Monthly | D27: 400 | E27: 15 | F27: =D27*E27 -> 6000 | G27: All
A28: Technology & infrastructure | B28: Claude API: Deemed Assistant evals on synthetic data | C28: From Jul 2027 | D28: 300 | E28: 6 | F28: =D28*E28 -> 1800 | G28: P6 prep
A29: Technology & infrastructure | B29: Error tracking and APM under a BAA | C29: From Apr 2027 | D29: 300 | E29: 9 | F29: =D29*E29 -> 2700 | G29: G4
... A32: Technology & infrastructure | B32: Workforce IT and security (Workspace, password manager, MDM, training) | C32: Monthly | D32: 200 | E32: 15 | F32: =D32*E32 -> 3000 | G32: G0
A33: Technology & infrastructure | B33: Laptops for new hires | C33: Per hire | D33: 2500 | E33: 3 | F33: =D33*E33 -> 7500
A34: Technology & infrastructure | B34: Hardware security keys (break-glass and workforce) | C34: One-time | D34: 600 | E34: 1 | F34: =D34*E34 -> 600 | G34: G1
A35: Business operations | B35: Cyber liability and technology E&O insurance ($2M) | C35: Bound Apr 2027 | D35: 1000 | E35: 9 | F35: =D35*E35 -> 9000 | G35: G4
A36: Business operations | B36: General liability / business owner's policy | C36: Monthly | D36: 100 | E36: 15 | F36: =D36*E36 -> 1500
A37: Business operations | B37: Accounting, bookkeeping, payroll service, tax filing | C37: Monthly | D37: 700 | E37: 15 | F37: =D37*E37 -> 10500
A38: Business operations | B38: Florida entity filings, registered agent, licenses | C38: One-time | D38: 1000 | E38: 1 | F38: =D38*E38 -> 1000
A39: Go-to-market | B39: Brand and bilingual marketing website | C39: Fixed fee | D39: 12000 | E39: 1 | F39: =D39*E39 -> 12000 | G39: P5
A40: Go-to-market | B40: Sales collateral, demo video, OSV-readiness guide | C40: Fixed fee | D40: 6000 | E40: 1 | F40: =D40*E40 -> 6000 | G40: P5
A41: Go-to-market | B41: CRM and sales tools | C41: From Jul 2027 | D41: 150 | E41: 6 | F41: =D41*E41 -> 900 | G41: P5
A42: Go-to-market | B42: FACHC conference and Florida events (2027) | C42: Booth, sponsorship | D42: 10000 | E42: 1 | F42: =D42*E42 -> 10000 | G42: P5
...

Sheet Operating budget
A1: Deemed Health · Annual operating budget, 2028–2031
A2: Costs to run the business after general availability. Scaled lines follow the Revenue sheet.
A3: Category | B3: Item | C3: Basis | D3: 2028 | E3: 2029 | F3: 2030 | G3: 2031
A4: People | B4: Founder / CEO and product owner | C4: $140k, +raise | D4: =IF(D$3>=2028,140000*(1+Raise)^(D$3-2028),0) -> 140000 | E4: =IF(E$3>=2028,140000*(1+Raise)^(E$3-2028),0) -> 145600 | F4: =IF(F$3>=2028,140000*(1+Raise)^(F$3-2028),0) -> 151424 | G4: =IF(G$3>=2028,140000*(1+Raise)^(G$3-2028),0) -> 157480.96
A5: People | B5: Senior full-stack engineer | C5: $177k, +raise | D5: =IF(D$3>=2028,176800*(1+Raise)^(D$3-2028),0) -> 176800 | E5: =IF(E$3>=2028,176800*(1+Raise)^(E$3-2028),0) -> 183872 | F5: =IF(F$3>=2028,176800*(1+Raise)^(F$3-2028),0) -> 191226.88 | G5: =IF(G$3>=2028,176800*(1+Raise)^(G$3-2028),0) -> 198875.96
A6: People | B6: Implementation & customer success lead | C6: $99k, +raise | D6: =IF(D$3>=2028,98800*(1+Raise)^(D$3-2028),0) -> 98800 | E6: =IF(E$3>=2028,98800*(1+Raise)^(E$3-2028),0) -> 102752 | F6: =IF(F$3>=2028,98800*(1+Raise)^(F$3-2028),0) -> 106862.08 | G6: =IF(G$3>=2028,98800*(1+Raise)^(G$3-2028),0) -> 111136.56
A7: People | B7: Sales & partnerships lead | C7: $109k base, +raise | D7: =IF(D$3>=2028,109200*(1+Raise)^(D$3-2028),0) -> 109200 | E7: =IF(E$3>=2028,109200*(1+Raise)^(E$3-2028),0) -> 113568 | F7: =IF(F$3>=2028,109200*(1+Raise)^(F$3-2028),0) -> 118110.72 | G7: =IF(G$3>=2028,109200*(1+Raise)^(G$3-2028),0) -> 122835.15
A8: People | B8: Bilingual implementation & support specialist | C8: From 2029 | D8: =IF(D$3>=2029,68000*(1+Raise)^(D$3-2028),0) -> 0 | E8: =IF(E$3>=2029,68000*(1+Raise)^(E$3-2028),0) -> 70720 | F8: =IF(F$3>=2029,68000*(1+Raise)^(F$3-2028),0) -> 73548.8 | G8: =IF(G$3>=2029,68000*(1+Raise)^(G$3-2028),0) -> 76490.752
A9: People | B9: Payroll taxes and benefits | C9: Load × salaries | D9: =Load*(D4+D5+D6+D7+D8) -> 115456 | E9: =Load*(E4+E5+E6+E7+E8) -> 135632.64 | F9: =Load*(F4+F5+F6+F7+F8) -> 141057.95 | G9: =Load*(G4+G5+G6+G7+G8) -> 146700.26
A10: People | B10: Sales commission | C10: Commission × new first-year value | D10: =Commission*Revenue!D9*Revenue!D7 -> 34560 | E10: =Commission*Revenue!E9*Revenue!E7 -> 41529.6 | F10: =Commission*Revenue!F9*Revenue!F7 -> 36664.704 | G10: =Commission*Revenue!G9*Revenue!G7 -> 31470.538
A11: People | B11: Fractional HRSA compliance advisor (regulatory watch, catalog changesets) | C11: $3,000/mo, +raise | D11: =36000*(1+Raise)^(D$3-2028) -> 36000 | E11: =36000*(1+Raise)^(E$3-2028) -> 37440 | F11: =36000*(1+Raise)^(F$3-2028) -> 38937.6 | G11: =36000*(1+Raise)^(G$3-2028) -> 40495.104
A12: People | B12: Fractional CISO / security advisor | C12: $3,500/mo | D12: 42000 | E12: 42000 | F12: 42000 | G12: 42000
A13: People | B13: Recruiting and background checks | C13: Years with a hire | D13: 0 | E13: 2500 | F13: 2500 | G13: 0
A14: Technology & infrastructure | B14: AWS (production, non-production, security, DR) | C14: (Base + per customer) × 12 | D14: =(AWSBase+AWSPerCust*Revenue!D6)*12 -> 39000 | E14: =(AWSBase+AWSPerCust*Revenue!E6)*12 -> 50700 | F14: =(AWSBase+AWSPerCust*Revenue!F6)*12 -> 62400 | G14: =(AWSBase+AWSPerCust*Revenue!G6)*12 -> 72300
A15: Technology & infrastructure | B15: Claude API for the Deemed Assistant (under BAA) | C15: Per customer × 12 | D15: =AIPerCust*Revenue!D6*12 -> 7200 | E15: =AIPerCust*Revenue!E6*12 -> 16560 | F15: =AIPerCust*Revenue!F6*12 -> 25920 | G15: =AIPerCust*Revenue!G6*12 -> 33840
A16: Technology & infrastructure | B16: Error tracking, APM, and log management under BAA | C16: $400 + $15/customer per mo | D16: =(400+15*Revenue!D6)*12 -> 5700 | E16: =(400+15*Revenue!E6)*12 -> 6870 | F16: =(400+15*Revenue!F6)*12 -> 8040 | G16: =(400+15*Revenue!G6)*12 -> 9030
A17: Technology & infrastructure | B17: Transactional email (Amazon SES) | C17: Monthly | D17: 600 | E17: 600 | F17: 900 | G17: 900
A18: Technology & infrastructure | B18: Compliance automation platform | C18: Annual | D18: 15000 | E18: 15000 | F18: 16000 | G18: 16000
A19: Technology & infrastructure | B19: Engineering tools (GitHub, Claude plans, CI minutes) | C19: Annual | D19: 10800 | E19: 10800 | F19: 14400 | G19: 14400
A20: Technology & infrastructure | B20: Workforce IT and security stack | C20: Per seat | D20: 3600 | E20: 4200 | F20: 4800 | G20: 4800
A21: Technology & infrastructure | B21: Equipment (new hires and refresh) | C21: Annual | D21: 2000 | E21: 4500 | F21: 4500 | G21: 3000
A22: Assurance & professional | B22: SOC 2 Type II audit | C22: Annual | D22: 30000 | E22: 30000 | F22: 32000 | G22: 32000
A23: Assurance & professional | B23: Annual penetration test | C23: Annual | D23: 25000 | E23: 25000 | F23: 27000 | G23: 27000
A24: Assurance & professional | B24: Targeted penetration test of the assistant panel | C24: Phase 6 gate | D24: 12000 | E24: 0 | F24: 0 | G24: 0
A25: Assurance & professional | B25: Accessibility re-audit and incident response tabletop | C25: Annual | D25: 9000 | E25: 9000 | F25: 9000 | G25: 9000
A26: Assurance & professional | B26: Legal (customer contracts and BAAs, regulatory questions) | C26: Annual | D26: 30000 | E26: 30000 | F26: 32000 | G26: 32000
A27: Assurance & professional | B27: Spanish translation of new content | C27: Annual | D27: 5000 | E27: 5000 | F27: 5000 | G27: 5000
A28: Assurance & professional | B28: Cyber liability, tech E&O, and general liability insurance | C28: Grows with revenue | D28: 19500 | E28: 21500 | F28: 23500 | G28: 25500
... A31: Go-to-market | B31: Digital marketing and content | C31: Annual | D31: 24000 | E31: 24000 | F31: 24000 | G31: 24000
A32: Go-to-market | B32: Travel (onsite implementation and sales in Florida) | C32: $12k + $1.5k per new customer | D32: =12000+1500*Revenue!D9 -> 21000 | E32: =12000+1500*Revenue!E9 -> 22500 | F32: =12000+1500*Revenue!F9 -> 21000 | G32: =12000+1500*Revenue!G9 -> 19500
A33: Go-to-market | B33: CRM and sales tools | C33: Annual | D33: 3600 | E33: 3600 | F33: 3600 | G33: 3600
A34: Go-to-market | B34: Payment processing | C34: PayFee × revenue | D34: =PayFee*Revenue!D11 -> 1800 | E34: =PayFee*Revenue!E11 -> 3831.36 | F34: =PayFee*Revenue!F11 -> 5859.7056 | G34: =PayFee*Revenue!G11 -> 7695.5763
B36: Subtotal: People | D36: =SUM(D4:D13) -> 752816 | E36: =SUM(E4:E13) -> 875614.24 | F36: =SUM(F4:F13) -> 902332.73 | G36: =SUM(G4:G13) -> 927485.28
B37: Subtotal: Technology & infrastructure | D37: =SUM(D14:D21) -> 83900 | E37: =SUM(E14:E21) -> 109230 | F37: =SUM(F14:F21) -> 136960 | G37: =SUM(G14:G21) -> 154270
B38: Subtotal: Assurance & professional | D38: =SUM(D22:D29) -> 142500 | E38: =SUM(E22:E29) -> 132500 | F38: =SUM(F22:F29) -> 141500 | G38: =SUM(G22:G29) -> 143500
B39: Subtotal: Go-to-market | D39: =SUM(D30:D34) -> 65400 | E39: =SUM(E30:E34) -> 68931.36 | F39: =SUM(F30:F34) -> 70459.706 | G39: =SUM(G30:G34) -> 70795.576
B40: Subtotal before contingency | D40: =SUM(D36:D39) -> 1044616 | E40: =SUM(E36:E39) -> 1186275.6 | F40: =SUM(F36:F39) -> 1251252.4 | G40: =SUM(G36:G39) -> 1296050.9
B41: Contingency | D41: =ContRun*D40 -> 104461.6 | E41: =ContRun*E40 -> 118627.56 | F41: =ContRun*F40 -> 125125.24 | G41: =ContRun*G40 -> 129605.09
B42: Total operating cost | D42: =D40+D41 -> 1149077.6 | E42: =E40+E41 -> 1304903.2 | F42: =F40+F41 -> 1376377.7 | G42: =G40+G41 -> 1425655.9
